<?xml version="1.0"?>
<robot
        xmlns:xacro="http://wiki.ros.org/xacro"
>
    <xacro:include filename="$(find kuka_resources)/urdf/common_constants.xacro"/>
    <xacro:include filename="$(find kuka_resources)/urdf/common_materials.xacro"/>

    <xacro:macro name="kuka_kr6r900sixx" params="prefix">
        <link name="${prefix}base_link">
            <visual>
                <origin xyz="0 0 0" rpy="0 0 0"/>
                <geometry>
                    <mesh filename="package://kuka_kr6_support/meshes/kr6_agilus/visual/base_link.dae"/>
                </geometry>
                <xacro:material_kuka_pedestal/>
            </visual>
            <collision>
                <origin xyz="0 0 0" rpy="0 0 0"/>
                <geometry>
                    <mesh filename="package://kuka_kr6_support/meshes/kr6_agilus/collision/base_link.stl"/>
                </geometry>
            </collision>
        </link>
        <link name="${prefix}link_1">
            <visual>
                <origin xyz="0 0 0" rpy="0 0 0"/>
                <geometry>
                    <mesh filename="package://kuka_kr6_support/meshes/kr6_agilus/visual/link_1.dae"/>
                </geometry>
                <xacro:material_kuka_orange/>
            </visual>
            <collision>
                <origin xyz="0 0 0" rpy="0 0 0"/>
                <geometry>
                    <mesh filename="package://kuka_kr6_support/meshes/kr6_agilus/collision/link_1.stl"/>
                </geometry>
            </collision>
        </link>
        <link name="${prefix}link_2">
            <visual>
                <origin xyz="0 0 0" rpy="0 0 0"/>
                <geometry>
                    <mesh filename="package://kuka_kr6_support/meshes/kr6r900sixx/visual/link_2.dae"/>
                </geometry>
                <xacro:material_kuka_orange/>
            </visual>
            <collision>
                <origin xyz="0 0 0" rpy="0 0 0"/>
                <geometry>
                    <mesh filename="package://kuka_kr6_support/meshes/kr6r900sixx/collision/link_2.stl"/>
                </geometry>
            </collision>
        </link>
        <link name="${prefix}link_3">
            <visual>
                <origin xyz="0 0 0" rpy="0 0 0"/>
                <geometry>
                    <mesh filename="package://kuka_kr6_support/meshes/kr6_agilus/visual/link_3.dae"/>
                </geometry>
                <xacro:material_kuka_orange/>
            </visual>
            <collision>
                <origin xyz="0 0 0" rpy="0 0 0"/>
                <geometry>
                    <mesh filename="package://kuka_kr6_support/meshes/kr6_agilus/collision/link_3.stl"/>
                </geometry>
            </collision>
        </link>
        <link name="${prefix}link_4">
            <visual>
                <origin xyz="0 0 0" rpy="0 0 0"/>
                <geometry>
                    <mesh filename="package://kuka_kr6_support/meshes/kr6r900sixx/visual/link_4.dae"/>
                </geometry>
                <xacro:material_kuka_orange/>
            </visual>
            <collision>
                <origin xyz="0 0 0" rpy="0 0 0"/>
                <geometry>
                    <mesh filename="package://kuka_kr6_support/meshes/kr6r900sixx/collision/link_4.stl"/>
                </geometry>
            </collision>
        </link>
        <link name="${prefix}link_5">
            <visual>
                <origin xyz="0 0 0" rpy="0 0 0"/>
                <geometry>
                    <mesh filename="package://kuka_kr6_support/meshes/kr6_agilus/visual/link_5.dae"/>
                </geometry>
                <xacro:material_kuka_orange/>
            </visual>
            <collision>
                <origin xyz="0 0 0" rpy="0 0 0"/>
                <geometry>
                    <mesh filename="package://kuka_kr6_support/meshes/kr6_agilus/collision/link_5.stl"/>
                </geometry>
            </collision>
        </link>
        <link name="${prefix}link_6">
            <visual>
                <origin xyz="0 0 0" rpy="0 0 0"/>
                <geometry>
                    <mesh filename="package://kuka_kr6_support/meshes/kr6_agilus/visual/link_6.dae"/>
                </geometry>
                <xacro:material_kuka_pedestal/>
            </visual>
            <collision>
                <origin xyz="0 0 0" rpy="0 0 0"/>
                <geometry>
                    <mesh filename="package://kuka_kr6_support/meshes/kr6_agilus/collision/link_6.stl"/>
                </geometry>
            </collision>
        </link>
        <link name="${prefix}tool0">
            <visual>
                <origin xyz="0.0 -0.032 0.0" rpy="0 0 0"/>
                <geometry>
                    <mesh filename="package://wsg_50_simulation/meshes/WSG50_110.stl" scale="1 1 1"/>
                    <!--box size="0.146 0.05 0.0735"/-->
                </geometry>
                <material name="grey">
                    <color rgba="0.64 0.32 0.16 1"/>
                </material>
            </visual>

            <collision>
                <origin xyz="0.0 -0.032 0.0" rpy="0 0 0"/>
                <geometry>
                    <!--box size="0.146 0.05 0.0735"/-->
                    <mesh filename="package://wsg_50_simulation/meshes/WSG50_110.stl" scale="1 1 1"/>
                </geometry>
            </collision>
        </link>

        <link name="wsg_50_gripper_left">
            <visual>
                <origin xyz="0.0 -0.032 0.0" rpy="0 0 0"/>
                <geometry>
                    <mesh filename="package://wsg_50_simulation/meshes/GUIDE_WSG50_110.stl" scale="0.001 0.001 0.001"/>
                    <!--box size="0.0175 0.03 0.024"/-->
                </geometry>
                <material name="grey">
                    <color rgba="0 0 0 0"/>
                </material>
            </visual>

            <collision>
                <origin xyz="0 -0.032 0.0" rpy="0 0 0"/>
                <geometry>
                    <!--box size="0.0175 0.03 0.024"/-->
                    <mesh filename="package://wsg_50_simulation/meshes/GUIDE_WSG50_110.stl" scale="0.001 0.001 0.001"/>
                </geometry>
            </collision>
        </link>

        <link name="wsg_50_finger_left">
            <visual>
                <origin xyz="0.0 -0.032 0.0" rpy="0 0 0"/>
                <geometry>
                    <mesh filename="package://wsg_50_simulation/meshes/WSG-FMF.stl" scale="0.001 0.001 0.001"/>
                </geometry>
                <material name="grey">
                    <color rgba="0 0 0 0"/>
                </material>
            </visual>

            <collision>
                <origin xyz="0 -0.032 0.0" rpy="0 0 0"/>
                <geometry>
                    <mesh filename="package://wsg_50_simulation/meshes/WSG-FMF.stl" scale="0.001 0.001 0.001"/>
                </geometry>
            </collision>
        </link>

        <link name="wsg_50_gripper_right">
            <visual>
                <origin xyz="0.0 0.032 0.0" rpy="0 0 0"/>
                <geometry>
                    <mesh filename="package://wsg_50_simulation/meshes/GUIDE_WSG50_110.stl" scale="0.001 0.001 0.001"/>
                    <!--box size="0.0175 0.03 0.024"/-->
                </geometry>
                <material name="grey">
                    <color rgba="0 0 0 0"/>
                </material>
            </visual>

            <collision>
                <origin xyz="0 0.032 0.0" rpy="0 0 0"/>
                <geometry>
                    <!--box size="0.0175 0.03 0.024"/-->
                    <mesh filename="package://wsg_50_simulation/meshes/GUIDE_WSG50_110.stl" scale="0.001 0.001 0.001"/>
                </geometry>
            </collision>
        </link>

        <link name="wsg_50_finger_right">
            <visual>
                <origin xyz="0.0 0.032 0.0" rpy="0 0 0"/>
                <geometry>
                    <mesh filename="package://wsg_50_simulation/meshes/WSG-FMF.stl" scale="0.001 0.001 0.001"/>
                </geometry>
                <material name="grey">
                    <color rgba="0 0 0 0"/>
                </material>
            </visual>
            <collision>
                <origin xyz="0 0.032 0.0" rpy="0 0 0"/>
                <geometry>
                    <mesh filename="package://wsg_50_simulation/meshes/WSG-FMF.stl" scale="0.001 0.001 0.001"/>
                </geometry>
            </collision>
        </link>

        <link name="wsg_50_joint_finger_center">
        </link>

        <joint name="${prefix}joint_a1" type="revolute">
            <origin xyz="0 0 0.400" rpy="0 0 0"/>
            <parent link="${prefix}base_link"/>
            <child link="${prefix}link_1"/>
            <axis xyz="0 0 -1"/>
            <limit effort="0" lower="${-DEG2RAD * 170}" upper="${DEG2RAD * 170}" velocity="${DEG2RAD * 360}"/>
        </joint>
        <joint name="${prefix}joint_a2" type="revolute">
            <origin xyz="0.025 0 0" rpy="0 0 0"/>
            <parent link="${prefix}link_1"/>
            <child link="${prefix}link_2"/>
            <axis xyz="0 1 0"/>
            <limit effort="0" lower="${-DEG2RAD * 190}" upper="${DEG2RAD * 45}" velocity="${DEG2RAD * 300}"/>
        </joint>
        <joint name="${prefix}joint_a3" type="revolute">
            <origin xyz="0.455 0 0" rpy="0 0 0"/>
            <parent link="${prefix}link_2"/>
            <child link="${prefix}link_3"/>
            <axis xyz="0 1 0"/>
            <limit effort="0" lower="${-DEG2RAD * 120}" upper="${DEG2RAD * 156}" velocity="${DEG2RAD * 360}"/>
        </joint>
        <joint name="${prefix}joint_a4" type="revolute">
            <origin xyz="0 0 0.035" rpy="0 0 0"/>
            <parent link="${prefix}link_3"/>
            <child link="${prefix}link_4"/>
            <axis xyz="-1 0 0"/>
            <limit effort="0" lower="${-DEG2RAD * 185}" upper="${DEG2RAD * 185}" velocity="${DEG2RAD * 381}"/>
        </joint>
        <joint name="${prefix}joint_a5" type="revolute">
            <origin xyz="0.420 0 0" rpy="0 0 0"/>
            <parent link="${prefix}link_4"/>
            <child link="${prefix}link_5"/>
            <axis xyz="0 1 0"/>
            <limit effort="0" lower="${-DEG2RAD * 120}" upper="${DEG2RAD * 120}" velocity="${DEG2RAD * 388}"/>
        </joint>
        <joint name="${prefix}joint_a6" type="revolute">
            <origin xyz="0.080 0 0" rpy="0 0 0"/>
            <parent link="${prefix}link_5"/>
            <child link="${prefix}link_6"/>
            <axis xyz="-1 0 0"/>
            <limit effort="0" lower="${-DEG2RAD * 350}" upper="${DEG2RAD * 350}" velocity="${DEG2RAD * 615}"/>
        </joint>
        <joint name="${prefix}joint_a6-tool0" type="fixed">
            <parent link="${prefix}link_6"/>
            <child link="${prefix}tool0"/>
            <origin xyz="0 0 0" rpy="0 ${DEG2RAD * 90} 0"/>
        </joint>

        <!-- ROS base_link to KUKA $ROBROOT coordinate system transform -->
        <link name="${prefix}base"/>
        <joint name="${prefix}base_link-base" type="fixed">
            <origin xyz="0 0 0" rpy="0 0 0"/>
            <parent link="${prefix}base_link"/>
            <child link="${prefix}base"/>
        </joint>

        <!--    <joint name="wsg_50_anterior_gripper_joint" type="fixed">-->
        <!--        <insert_block name="origin"/>-->
        <!--        <parent link="${prefix}link_6"/>-->
        <!--        <child link="${prefix}tool0"/>-->
        <!--    </joint>-->

        <!-- GRIPPER LEFT -->
        <joint name="wsg_50_finger_left_joint" type="prismatic">
            <limit lower="-0.055" upper="-0.0027" effort="1.0" velocity="1.0"/>
            <origin xyz="0 0 0" rpy="0 0 0"/>      <!--origin xyz="-0.0067 0 0.049" rpy="0 0 0" /-->
            <parent link="${prefix}tool0"/>
            <child link="wsg_50_gripper_left"/>
            <dynamics friction="100" damping="100"/>
            <axis xyz="1 0 0"/>
            <limit effort="100" velocity="100"/>
        </joint>


        <!-- LEFT FINGER -->
        <joint name="wsg_50_guide_joint_finger_left" type="fixed">
            <origin xyz="0 0 0.023" rpy="0 0 0"/>
            <parent link="wsg_50_gripper_left"/>
            <child link="wsg_50_finger_left"/>
            <dynamics friction="100" damping="100"/>
            <axis xyz="1 0 0"/>
            <limit effort="100" velocity="100"/>
        </joint>


        <!-- GRIPPER RIGHT -->

        <joint name="wsg_50_finger_right_joint" type="prismatic">
            <limit lower="0.0027" upper="0.055" effort="1.0" velocity="1.0"/>
            <origin xyz="0 0 0" rpy="0 0 3.14159"/>
            <parent link="${prefix}tool0"/>
            <child link="wsg_50_gripper_right"/>
            <axis xyz="-1 0 0"/>
            <dynamics friction="100" damping="100"/>
            <limit effort="100" velocity="100"/>
        </joint>

        <!-- RIGHT FINGER -->

        <joint name="wsg_50_guide_joint_finger_right" type="fixed">
            <origin xyz="0 0 0.023" rpy="0 0 0"/>
            <parent link="wsg_50_gripper_right"/>
            <child link="wsg_50_finger_right"/>
            <dynamics friction="100" damping="100"/>
            <axis xyz="1 0 0"/>
            <limit effort="100" velocity="100"/>
        </joint>

        <joint name="wsg_50_joint_finger_center" type="fixed">
            <origin xyz="0.0 -0.032 0.145" rpy="0 0 0"/>
            <parent link="${prefix}tool0"/>
            <child link="wsg_50_joint_finger_center"/>
        </joint>
    </xacro:macro>
</robot>